<?xml version="1.0" ?>
<robot name="braco" xmlns:xacro="http://www.ros.org/wiki/xacro">

<xacro:include filename="$(find braco_description)/urdf/materials.xacro" />
<xacro:include filename="$(find braco_description)/urdf/braco.trans" />
<xacro:include filename="$(find braco_description)/urdf/braco.gazebo" />
<link name="base_link">
  <inertial>
    <origin rpy="0 0 0" xyz="1.7530925309878173e-17 -4.54861709507948e-18 0.02187352138307566"/>
    <mass value="0.08783440670094944"/>
    <inertia ixx="0.000167" ixy="0.0" ixz="-0.0" iyy="0.000167" iyz="0.0" izz="0.000245"/>
  </inertial>
  <visual>
    <origin rpy="0 0 0" xyz="0 0 0"/>
    <geometry>
      <mesh filename="package://braco_description/meshes/base_link.stl" scale="0.001 0.001 0.001"/>
    </geometry>
    <material name="silver"/>
  </visual>
  <collision>
    <origin rpy="0 0 0" xyz="0 0 0"/>
    <geometry>
      <mesh filename="package://braco_description/meshes/base_link.stl" scale="0.001 0.001 0.001"/>
    </geometry>
  </collision>
</link>

<link name="servo_left_1">
  <inertial>
    <origin rpy="0 0 0" xyz="-0.0014473150385015854 0.1421669334642504 -0.006915072172979028"/>
    <mass value="0.25257832542625036"/>
    <inertia ixx="6.8e-05" ixy="-0.0" ixz="0.0" iyy="4.4e-05" iyz="1e-06" izz="4.1e-05"/>
  </inertial>
  <visual>
    <origin rpy="0 0 0" xyz="-0.002899 0.093141 -0.112109"/>
    <geometry>
      <mesh filename="package://braco_description/meshes/servo_left_1.stl" scale="0.001 0.001 0.001"/>
    </geometry>
    <material name="silver"/>
  </visual>
  <collision>
    <origin rpy="0 0 0" xyz="-0.002899 0.093141 -0.112109"/>
    <geometry>
      <mesh filename="package://braco_description/meshes/servo_left_1.stl" scale="0.001 0.001 0.001"/>
    </geometry>
  </collision>
</link>

<link name="servo_right_1">
  <inertial>
    <origin rpy="0 0 0" xyz="0.06544272704404532 -0.14216641850044148 0.07250492782702281"/>
    <mass value="0.25257832542625036"/>
    <inertia ixx="6.8e-05" ixy="-0.0" ixz="-0.0" iyy="4.4e-05" iyz="-1e-06" izz="4.1e-05"/>
  </inertial>
  <visual>
    <origin rpy="0 0 0" xyz="0.064 -0.093939 -0.032689"/>
    <geometry>
      <mesh filename="package://braco_description/meshes/servo_right_1.stl" scale="0.001 0.001 0.001"/>
    </geometry>
    <material name="silver"/>
  </visual>
  <collision>
    <origin rpy="0 0 0" xyz="0.064 -0.093939 -0.032689"/>
    <geometry>
      <mesh filename="package://braco_description/meshes/servo_right_1.stl" scale="0.001 0.001 0.001"/>
    </geometry>
  </collision>
</link>

<link name="Center_arm_v1_1">
  <inertial>
    <origin rpy="0 0 0" xyz="-0.0007068682064791942 0.009887184158139134 -0.05780205339226316"/>
    <mass value="0.24743903954578314"/>
    <inertia ixx="0.000566" ixy="0.0" ixz="-5e-06" iyy="0.000605" iyz="-0.0" izz="7.6e-05"/>
  </inertial>
  <visual>
    <origin rpy="0 0 0" xyz="-0.168543 0.011691 -0.194405"/>
    <geometry>
      <mesh filename="package://braco_description/meshes/Center_arm_v1_1.stl" scale="0.001 0.001 0.001"/>
    </geometry>
    <material name="silver"/>
  </visual>
  <collision>
    <origin rpy="0 0 0" xyz="-0.168543 0.011691 -0.194405"/>
    <geometry>
      <mesh filename="package://braco_description/meshes/Center_arm_v1_1.stl" scale="0.001 0.001 0.001"/>
    </geometry>
  </collision>
</link>

<link name="Center_arm_bearing_guide_v1_1">
  <inertial>
    <origin rpy="0 0 0" xyz="-0.008485716956284667 0.003221962356881842 0.008485254227916045"/>
    <mass value="0.0033035453927957375"/>
    <inertia ixx="0.0" ixy="-0.0" ixz="0.0" iyy="0.0" iyz="-0.0" izz="0.0"/>
  </inertial>
  <visual>
    <origin rpy="0 0 0" xyz="-0.177029 -0.008309 -0.18592"/>
    <geometry>
      <mesh filename="package://braco_description/meshes/Center_arm_bearing_guide_v1_1.stl" scale="0.001 0.001 0.001"/>
    </geometry>
    <material name="silver"/>
  </visual>
  <collision>
    <origin rpy="0 0 0" xyz="-0.177029 -0.008309 -0.18592"/>
    <geometry>
      <mesh filename="package://braco_description/meshes/Center_arm_bearing_guide_v1_1.stl" scale="0.001 0.001 0.001"/>
    </geometry>
  </collision>
</link>

<link name="Center_arm_bearing_guide_v1__1__1">
  <inertial>
    <origin rpy="0 0 0" xyz="-0.008485716956255163 0.003221962356880064 -0.008485745772046652"/>
    <mass value="0.0033035453927957375"/>
    <inertia ixx="0.0" ixy="0.0" ixz="-0.0" iyy="0.0" iyz="0.0" izz="0.0"/>
  </inertial>
  <visual>
    <origin rpy="0 0 0" xyz="-0.177029 -0.008309 -0.085391"/>
    <geometry>
      <mesh filename="package://braco_description/meshes/Center_arm_bearing_guide_v1__1__1.stl" scale="0.001 0.001 0.001"/>
    </geometry>
    <material name="silver"/>
  </visual>
  <collision>
    <origin rpy="0 0 0" xyz="-0.177029 -0.008309 -0.085391"/>
    <geometry>
      <mesh filename="package://braco_description/meshes/Center_arm_bearing_guide_v1__1__1.stl" scale="0.001 0.001 0.001"/>
    </geometry>
  </collision>
</link>

<link name="Center_arm_bearing_guide_clamp_v1_1">
  <inertial>
    <origin rpy="0 0 0" xyz="2.8304380533805684e-07 0.0016578450305459944 2.542279528283675e-07"/>
    <mass value="0.00026744770959091237"/>
    <inertia ixx="0.0" ixy="-0.0" ixz="0.0" iyy="0.0" iyz="0.0" izz="0.0"/>
  </inertial>
  <visual>
    <origin rpy="0 0 0" xyz="-0.168543 -0.021709 -0.194405"/>
    <geometry>
      <mesh filename="package://braco_description/meshes/Center_arm_bearing_guide_clamp_v1_1.stl" scale="0.001 0.001 0.001"/>
    </geometry>
    <material name="silver"/>
  </visual>
  <collision>
    <origin rpy="0 0 0" xyz="-0.168543 -0.021709 -0.194405"/>
    <geometry>
      <mesh filename="package://braco_description/meshes/Center_arm_bearing_guide_clamp_v1_1.stl" scale="0.001 0.001 0.001"/>
    </geometry>
  </collision>
</link>

<link name="ombro_1">
  <inertial>
    <origin rpy="0 0 0" xyz="0.08425500605814484 0.024406441382175036 0.039929756958307056"/>
    <mass value="0.488316525379642"/>
    <inertia ixx="0.000841" ixy="-3.4e-05" ixz="-0.000637" iyy="0.001965" iyz="-1.6e-05" izz="0.001884"/>
  </inertial>
  <visual>
    <origin rpy="0 0 0" xyz="-0.001443 0.023001 -0.11517"/>
    <geometry>
      <mesh filename="package://braco_description/meshes/ombro_1.stl" scale="0.001 0.001 0.001"/>
    </geometry>
    <material name="silver"/>
  </visual>
  <collision>
    <origin rpy="0 0 0" xyz="-0.001443 0.023001 -0.11517"/>
    <geometry>
      <mesh filename="package://braco_description/meshes/ombro_1.stl" scale="0.001 0.001 0.001"/>
    </geometry>
  </collision>
</link>

<link name="servo_elbow_1">
  <inertial>
    <origin rpy="0 0 0" xyz="0.11594994326799538 0.20794860786324101 -0.05484182605242849"/>
    <mass value="0.2525786066068201"/>
    <inertia ixx="4.6e-05" ixy="-0.0" ixz="-1.1e-05" iyy="4.4e-05" iyz="-0.0" izz="6.3e-05"/>
  </inertial>
  <visual>
    <origin rpy="0 0 0" xyz="-0.043552 0.244866 -0.245031"/>
    <geometry>
      <mesh filename="package://braco_description/meshes/servo_elbow_1.stl" scale="0.001 0.001 0.001"/>
    </geometry>
    <material name="silver"/>
  </visual>
  <collision>
    <origin rpy="0 0 0" xyz="-0.043552 0.244866 -0.245031"/>
    <geometry>
      <mesh filename="package://braco_description/meshes/servo_elbow_1.stl" scale="0.001 0.001 0.001"/>
    </geometry>
  </collision>
</link>

<link name="servo_punho_rot_1">
  <inertial>
    <origin rpy="0 0 0" xyz="0.12479196273098876 -0.10986496796742719 -0.2166544630735875"/>
    <mass value="0.25257832542625036"/>
    <inertia ixx="4.4e-05" ixy="-0.0" ixz="1e-06" iyy="6.8e-05" iyz="0.0" izz="4.1e-05"/>
  </inertial>
  <visual>
    <origin rpy="0 0 0" xyz="-0.105174 -0.110262 -0.30322"/>
    <geometry>
      <mesh filename="package://braco_description/meshes/servo_punho_rot_1.stl" scale="0.001 0.001 0.001"/>
    </geometry>
    <material name="silver"/>
  </visual>
  <collision>
    <origin rpy="0 0 0" xyz="-0.105174 -0.110262 -0.30322"/>
    <geometry>
      <mesh filename="package://braco_description/meshes/servo_punho_rot_1.stl" scale="0.001 0.001 0.001"/>
    </geometry>
  </collision>
</link>

<link name="servo_punho_xy_1">
  <inertial>
    <origin rpy="0 0 0" xyz="0.009976323814758825 -0.025226418500438767 2.8228800974527957e-07"/>
    <mass value="0.25257832542625036"/>
    <inertia ixx="4.1e-05" ixy="1e-06" ixz="0.0" iyy="4.4e-05" iyz="-0.0" izz="6.8e-05"/>
  </inertial>
  <visual>
    <origin rpy="0 0 0" xyz="-0.168543 0.011691 -0.076905"/>
    <geometry>
      <mesh filename="package://braco_description/meshes/servo_punho_xy_1.stl" scale="0.001 0.001 0.001"/>
    </geometry>
    <material name="silver"/>
  </visual>
  <collision>
    <origin rpy="0 0 0" xyz="-0.168543 0.011691 -0.076905"/>
    <geometry>
      <mesh filename="package://braco_description/meshes/servo_punho_xy_1.stl" scale="0.001 0.001 0.001"/>
    </geometry>
  </collision>
</link>

<link name="punho_1">
  <inertial>
    <origin rpy="0 0 0" xyz="-0.12859312744504028 0.10517389824420881 0.02895937574638175"/>
    <mass value="0.21880690583277723"/>
    <inertia ixx="0.000235" ixy="1.1e-05" ixz="-7e-06" iyy="0.000273" iyz="0.0" izz="0.000371"/>
  </inertial>
  <visual>
    <origin rpy="0 0 0" xyz="-0.333684 0.102528 -0.048905"/>
    <geometry>
      <mesh filename="package://braco_description/meshes/punho_1.stl" scale="0.001 0.001 0.001"/>
    </geometry>
    <material name="silver"/>
  </visual>
  <collision>
    <origin rpy="0 0 0" xyz="-0.333684 0.102528 -0.048905"/>
    <geometry>
      <mesh filename="package://braco_description/meshes/punho_1.stl" scale="0.001 0.001 0.001"/>
    </geometry>
  </collision>
</link>

<link name="Center_arm_bearing_guide_clamp_v1_punho_1">
  <inertial>
    <origin rpy="0 0 0" xyz="2.8304370869314255e-07 0.0016578450305454705 2.542280483353032e-07"/>
    <mass value="0.00026744770959091237"/>
    <inertia ixx="0.0" ixy="0.0" ixz="0.0" iyy="0.0" iyz="-0.0" izz="0.0"/>
  </inertial>
  <visual>
    <origin rpy="0 0 0" xyz="-0.168543 -0.021709 -0.076905"/>
    <geometry>
      <mesh filename="package://braco_description/meshes/Center_arm_bearing_guide_clamp_v1_punho_1.stl" scale="0.001 0.001 0.001"/>
    </geometry>
    <material name="silver"/>
  </visual>
  <collision>
    <origin rpy="0 0 0" xyz="-0.168543 -0.021709 -0.076905"/>
    <geometry>
      <mesh filename="package://braco_description/meshes/Center_arm_bearing_guide_clamp_v1_punho_1.stl" scale="0.001 0.001 0.001"/>
    </geometry>
  </collision>
</link>

<link name="Base_servo_mount_left_1">
  <inertial>
    <origin rpy="0 0 0" xyz="-0.01587454048783796 0.00020637077105224721 0.042452933406575105"/>
    <mass value="0.04710420541299449"/>
    <inertia ixx="2.1e-05" ixy="0.0" ixz="0.0" iyy="3.9e-05" iyz="0.0" izz="2e-05"/>
  </inertial>
  <visual>
    <origin rpy="0 0 0" xyz="-0.017324 -0.037609 -0.072"/>
    <geometry>
      <mesh filename="package://braco_description/meshes/Base_servo_mount_left_1.stl" scale="0.001 0.001 0.001"/>
    </geometry>
    <material name="silver"/>
  </visual>
  <collision>
    <origin rpy="0 0 0" xyz="-0.017324 -0.037609 -0.072"/>
    <geometry>
      <mesh filename="package://braco_description/meshes/Base_servo_mount_left_1.stl" scale="0.001 0.001 0.001"/>
    </geometry>
  </collision>
</link>

<link name="Base_servo_mount_right_v1_1">
  <inertial>
    <origin rpy="0 0 0" xyz="-0.015875047506617307 -0.00020585580724299946 0.042452933406575896"/>
    <mass value="0.04710420541299451"/>
    <inertia ixx="2.1e-05" ixy="-0.0" ixz="-0.0" iyy="3.9e-05" iyz="-0.0" izz="2e-05"/>
  </inertial>
  <visual>
    <origin rpy="0 0 0" xyz="-0.01732 0.036811 -0.072"/>
    <geometry>
      <mesh filename="package://braco_description/meshes/Base_servo_mount_right_v1_1.stl" scale="0.001 0.001 0.001"/>
    </geometry>
    <material name="silver"/>
  </visual>
  <collision>
    <origin rpy="0 0 0" xyz="-0.01732 0.036811 -0.072"/>
    <geometry>
      <mesh filename="package://braco_description/meshes/Base_servo_mount_right_v1_1.stl" scale="0.001 0.001 0.001"/>
    </geometry>
  </collision>
</link>

<link name="corpo_garra_1">
  <inertial>
    <origin rpy="0 0 0" xyz="0.03690022235162099 3.972526448471712e-09 -0.004369638500211395"/>
    <mass value="0.0475742677792808"/>
    <inertia ixx="2e-05" ixy="-0.0" ixz="2e-06" iyy="5.2e-05" iyz="0.0" izz="4.3e-05"/>
  </inertial>
  <visual>
    <origin rpy="0 0 0" xyz="-0.255193 -0.000397 -0.076589"/>
    <geometry>
      <mesh filename="package://braco_description/meshes/corpo_garra_1.stl" scale="0.001 0.001 0.001"/>
    </geometry>
    <material name="silver"/>
  </visual>
  <collision>
    <origin rpy="0 0 0" xyz="-0.255193 -0.000397 -0.076589"/>
    <geometry>
      <mesh filename="package://braco_description/meshes/corpo_garra_1.stl" scale="0.001 0.001 0.001"/>
    </geometry>
  </collision>
</link>

<link name="Bearing_guide_v1_1">
  <inertial>
    <origin rpy="0 0 0" xyz="-3.612866644742141e-07 3.972064578563073e-09 0.0172504961553627"/>
    <mass value="0.0016815613439380714"/>
    <inertia ixx="0.0" ixy="0.0" ixz="0.0" iyy="0.0" iyz="-0.0" izz="0.0"/>
  </inertial>
  <visual>
    <origin rpy="0 0 0" xyz="-0.329943 -0.000397 -0.059339"/>
    <geometry>
      <mesh filename="package://braco_description/meshes/Bearing_guide_v1_1.stl" scale="0.001 0.001 0.001"/>
    </geometry>
    <material name="silver"/>
  </visual>
  <collision>
    <origin rpy="0 0 0" xyz="-0.329943 -0.000397 -0.059339"/>
    <geometry>
      <mesh filename="package://braco_description/meshes/Bearing_guide_v1_1.stl" scale="0.001 0.001 0.001"/>
    </geometry>
  </collision>
</link>

<link name="Bearing_top-bottom_bushing_v1_1">
  <inertial>
    <origin rpy="0 0 0" xyz="-3.6128666475176985e-07 3.972463791398172e-09 -0.00174950384463754"/>
    <mass value="0.0016106179771745465"/>
    <inertia ixx="0.0" ixy="-0.0" ixz="0.0" iyy="0.0" iyz="0.0" izz="0.0"/>
  </inertial>
  <visual>
    <origin rpy="0 0 0" xyz="-0.329943 -0.000397 -0.088839"/>
    <geometry>
      <mesh filename="package://braco_description/meshes/Bearing_top-bottom_bushing_v1_1.stl" scale="0.001 0.001 0.001"/>
    </geometry>
    <material name="silver"/>
  </visual>
  <collision>
    <origin rpy="0 0 0" xyz="-0.329943 -0.000397 -0.088839"/>
    <geometry>
      <mesh filename="package://braco_description/meshes/Bearing_top-bottom_bushing_v1_1.stl" scale="0.001 0.001 0.001"/>
    </geometry>
  </collision>
</link>

<link name="Bearing_top-bottom_bushing_v1__1__1">
  <inertial>
    <origin rpy="0 0 0" xyz="-3.6128666464074755e-07 3.9724636844958375e-09 0.0017504961553625048"/>
    <mass value="0.0016106179771745465"/>
    <inertia ixx="0.0" ixy="-0.0" ixz="-0.0" iyy="0.0" iyz="0.0" izz="0.0"/>
  </inertial>
  <visual>
    <origin rpy="0 0 0" xyz="-0.329943 -0.000397 -0.064339"/>
    <geometry>
      <mesh filename="package://braco_description/meshes/Bearing_top-bottom_bushing_v1__1__1.stl" scale="0.001 0.001 0.001"/>
    </geometry>
    <material name="silver"/>
  </visual>
  <collision>
    <origin rpy="0 0 0" xyz="-0.329943 -0.000397 -0.064339"/>
    <geometry>
      <mesh filename="package://braco_description/meshes/Bearing_top-bottom_bushing_v1__1__1.stl" scale="0.001 0.001 0.001"/>
    </geometry>
  </collision>
</link>

<link name="Bearing_center_bushing_v1_1">
  <inertial>
    <origin rpy="0 0 0" xyz="0.08272163871333552 0.03771400397246374 0.1175364961553626"/>
    <mass value="0.0034513242368025996"/>
    <inertia ixx="0.0" ixy="0.0" ixz="0.0" iyy="0.0" iyz="0.0" izz="0.0"/>
  </inertial>
  <visual>
    <origin rpy="0 0 0" xyz="-0.247221 0.037317 0.040947"/>
    <geometry>
      <mesh filename="package://braco_description/meshes/Bearing_center_bushing_v1_1.stl" scale="0.001 0.001 0.001"/>
    </geometry>
    <material name="silver"/>
  </visual>
  <collision>
    <origin rpy="0 0 0" xyz="-0.247221 0.037317 0.040947"/>
    <geometry>
      <mesh filename="package://braco_description/meshes/Bearing_center_bushing_v1_1.stl" scale="0.001 0.001 0.001"/>
    </geometry>
  </collision>
</link>

<link name="servo_garra_1">
  <inertial>
    <origin rpy="0 0 0" xyz="0.037777710886314486 -0.022783770578142893 0.08636982017301603"/>
    <mass value="0.25257832542625036"/>
    <inertia ixx="4.1e-05" ixy="-0.0" ixz="1e-06" iyy="6.8e-05" iyz="0.0" izz="4.4e-05"/>
  </inertial>
  <visual>
    <origin rpy="0 0 0" xyz="-0.257221 -0.023183 0.040947"/>
    <geometry>
      <mesh filename="package://braco_description/meshes/servo_garra_1.stl" scale="0.001 0.001 0.001"/>
    </geometry>
    <material name="silver"/>
  </visual>
  <collision>
    <origin rpy="0 0 0" xyz="-0.257221 -0.023183 0.040947"/>
    <geometry>
      <mesh filename="package://braco_description/meshes/servo_garra_1.stl" scale="0.001 0.001 0.001"/>
    </geometry>
  </collision>
</link>

<link name="Gripper_120T_v1_1">
  <inertial>
    <origin rpy="0 0 0" xyz="0.010502021200330447 0.01817352441983682 0.006028973064765769"/>
    <mass value="0.031315152970389164"/>
    <inertia ixx="1e-05" ixy="-4e-06" ixz="-3e-06" iyy="4e-05" iyz="-0.0" izz="4.8e-05"/>
  </inertial>
  <visual>
    <origin rpy="0 0 0" xyz="-0.329943 -0.000397 -0.067839"/>
    <geometry>
      <mesh filename="package://braco_description/meshes/Gripper_120T_v1_1.stl" scale="0.001 0.001 0.001"/>
    </geometry>
    <material name="silver"/>
  </visual>
  <collision>
    <origin rpy="0 0 0" xyz="-0.329943 -0.000397 -0.067839"/>
    <geometry>
      <mesh filename="package://braco_description/meshes/Gripper_120T_v1_1.stl" scale="0.001 0.001 0.001"/>
    </geometry>
  </collision>
</link>

<link name="Gripper_72T_v1_1">
  <inertial>
    <origin rpy="0 0 0" xyz="0.020483598648375678 -0.01768686032720037 -0.0012211351915923235"/>
    <mass value="0.0250024753894087"/>
    <inertia ixx="4e-06" ixy="2e-06" ixz="2e-06" iyy="2e-05" iyz="-0.0" izz="2.2e-05"/>
  </inertial>
  <visual>
    <origin rpy="0 0 0" xyz="-0.329943 -0.000397 -0.080339"/>
    <geometry>
      <mesh filename="package://braco_description/meshes/Gripper_72T_v1_1.stl" scale="0.001 0.001 0.001"/>
    </geometry>
    <material name="silver"/>
  </visual>
  <collision>
    <origin rpy="0 0 0" xyz="-0.329943 -0.000397 -0.080339"/>
    <geometry>
      <mesh filename="package://braco_description/meshes/Gripper_72T_v1_1.stl" scale="0.001 0.001 0.001"/>
    </geometry>
  </collision>
</link>

<link name="Servo_gear_v1_1">
  <inertial>
    <origin rpy="0 0 0" xyz="-3.2988473608330793e-07 2.574818630455395e-07 0.004318374627694327"/>
    <mass value="0.010154744217590462"/>
    <inertia ixx="1e-06" ixy="-0.0" ixz="0.0" iyy="1e-06" iyz="0.0" izz="1e-06"/>
  </inertial>
  <visual>
    <origin rpy="0 0 0" xyz="-0.285023 -0.000399 -0.070649"/>
    <geometry>
      <mesh filename="package://braco_description/meshes/Servo_gear_v1_1.stl" scale="0.001 0.001 0.001"/>
    </geometry>
    <material name="silver"/>
  </visual>
  <collision>
    <origin rpy="0 0 0" xyz="-0.285023 -0.000399 -0.070649"/>
    <geometry>
      <mesh filename="package://braco_description/meshes/Servo_gear_v1_1.stl" scale="0.001 0.001 0.001"/>
    </geometry>
  </collision>
</link>

<link name="tampa_1">
  <inertial>
    <origin rpy="0 0 0" xyz="-6.093836564699504e-06 -1.681177278100045e-06 0.0661167042349627"/>
    <mass value="0.0342597144271648"/>
    <inertia ixx="2.9e-05" ixy="0.0" ixz="0.0" iyy="2.9e-05" iyz="0.0" izz="5.4e-05"/>
  </inertial>
  <visual>
    <origin rpy="0 0 0" xyz="-0.0 -0.0 -0.003"/>
    <geometry>
      <mesh filename="package://braco_description/meshes/tampa_1.stl" scale="0.001 0.001 0.001"/>
    </geometry>
    <material name="silver"/>
  </visual>
  <collision>
    <origin rpy="0 0 0" xyz="-0.0 -0.0 -0.003"/>
    <geometry>
      <mesh filename="package://braco_description/meshes/tampa_1.stl" scale="0.001 0.001 0.001"/>
    </geometry>
  </collision>
</link>

<joint name="Rigid28" type="fixed">
  <origin rpy="0 0 0" xyz="-0.014425 -0.13075 0.040109"/>
  <parent link="Base_servo_mount_left_1"/>
  <child link="servo_left_1"/>
</joint>

<joint name="Rigid37" type="fixed">
  <origin rpy="0 0 0" xyz="-0.08132 0.13075 -0.039311"/>
  <parent link="Base_servo_mount_right_v1_1"/>
  <child link="servo_right_1"/>
</joint>

<joint name="Rev52" type="continuous">
  <origin rpy="0 0 0" xyz="0.124991 0.233175 -0.050626"/>
  <parent link="servo_elbow_1"/>
  <child link="Center_arm_v1_1"/>
  <axis xyz="0.0 1.0 -0.0"/>
</joint>

<joint name="Rigid54" type="fixed">
  <origin rpy="0 0 0" xyz="0.008486 0.02 -0.008485"/>
  <parent link="Center_arm_v1_1"/>
  <child link="Center_arm_bearing_guide_v1_1"/>
</joint>

<joint name="Rigid56" type="fixed">
  <origin rpy="0 0 0" xyz="0.008486 0.02 -0.109014"/>
  <parent link="Center_arm_v1_1"/>
  <child link="Center_arm_bearing_guide_v1__1__1"/>
</joint>

<joint name="Rigid58" type="fixed">
  <origin rpy="0 0 0" xyz="-0.008486 0.0134 0.008485"/>
  <parent link="Center_arm_bearing_guide_v1_1"/>
  <child link="Center_arm_bearing_guide_clamp_v1_1"/>
</joint>

<joint name="Rev63" type="continuous">
  <origin rpy="0 0 0" xyz="0.065443 -0.11694 0.082481"/>
  <parent link="servo_right_1"/>
  <child link="ombro_1"/>
  <axis xyz="0.0 1.0 0.0"/>
</joint>

<joint name="Rigid65" type="fixed">
  <origin rpy="0 0 0" xyz="0.042109 -0.221865 0.129861"/>
  <parent link="ombro_1"/>
  <child link="servo_elbow_1"/>
</joint>

<joint name="Rigid70" type="fixed">
  <origin rpy="0 0 0" xyz="-0.22851 0.21279 0.254315"/>
  <parent link="punho_1"/>
  <child link="servo_punho_rot_1"/>
</joint>

<joint name="Rev71" type="continuous">
  <origin rpy="0 0 0" xyz="0.0 0.0 -0.1175"/>
  <parent link="Center_arm_v1_1"/>
  <child link="servo_punho_xy_1"/>
  <axis xyz="-0.0 -1.0 0.0"/>
</joint>

<joint name="Rigid72" type="fixed">
  <origin rpy="0 0 0" xyz="0.165141 -0.090837 -0.028"/>
  <parent link="servo_punho_xy_1"/>
  <child link="punho_1"/>
</joint>

<joint name="Rigid74" type="fixed">
  <origin rpy="0 0 0" xyz="-0.008486 0.0134 -0.008486"/>
  <parent link="Center_arm_bearing_guide_v1__1__1"/>
  <child link="Center_arm_bearing_guide_clamp_v1_punho_1"/>
</joint>

<joint name="Rigid77" type="fixed">
  <origin rpy="0 0 0" xyz="0.017324 0.037609 0.069"/>
  <parent link="tampa_1"/>
  <child link="Base_servo_mount_left_1"/>
</joint>

<joint name="Rigid78" type="fixed">
  <origin rpy="0 0 0" xyz="0.01732 -0.036811 0.069"/>
  <parent link="tampa_1"/>
  <child link="Base_servo_mount_right_v1_1"/>
</joint>

<joint name="Rev81" type="continuous">
  <origin rpy="0 0 0" xyz="0.150019 -0.109865 -0.226631"/>
  <parent link="servo_punho_rot_1"/>
  <child link="corpo_garra_1"/>
  <axis xyz="1.0 0.0 0.0"/>
</joint>

<joint name="Rigid82" type="fixed">
  <origin rpy="0 0 0" xyz="0.07475 0.0 -0.01725"/>
  <parent link="corpo_garra_1"/>
  <child link="Bearing_guide_v1_1"/>
</joint>

<joint name="Rigid83" type="fixed">
  <origin rpy="0 0 0" xyz="0.07475 0.0 0.01225"/>
  <parent link="corpo_garra_1"/>
  <child link="Bearing_top-bottom_bushing_v1_1"/>
</joint>

<joint name="Rigid84" type="fixed">
  <origin rpy="0 0 0" xyz="0.07475 0.0 -0.01225"/>
  <parent link="corpo_garra_1"/>
  <child link="Bearing_top-bottom_bushing_v1__1__1"/>
</joint>

<joint name="Rigid85" type="fixed">
  <origin rpy="0 0 0" xyz="-0.007972 -0.037714 -0.117536"/>
  <parent link="corpo_garra_1"/>
  <child link="Bearing_center_bushing_v1_1"/>
</joint>

<joint name="Rigid86" type="fixed">
  <origin rpy="0 0 0" xyz="0.002028 0.022786 -0.117536"/>
  <parent link="corpo_garra_1"/>
  <child link="servo_garra_1"/>
</joint>

<joint name="Rev87" type="revolute">
  <origin rpy="0 0 0" xyz="0.0 0.0 0.0035"/>
  <parent link="Bearing_top-bottom_bushing_v1__1__1"/>
  <child link="Gripper_120T_v1_1"/>
  <axis xyz="-0.0 0.0 1.0"/>
  <limit effort="100" lower="0.0" upper="0.785398" velocity="100"/>
</joint>

<joint name="Rev88" type="revolute">
  <origin rpy="0 0 0" xyz="0.082722 0.037714 0.121286"/>
  <parent link="Bearing_center_bushing_v1_1"/>
  <child link="Gripper_72T_v1_1"/>
  <axis xyz="-0.0 0.0 1.0"/>
  <limit effort="100" lower="-0.785398" upper="0.0" velocity="100"/>
</joint>

<joint name="Rev89" type="continuous">
  <origin rpy="0 0 0" xyz="0.027802 -0.022784 0.111596"/>
  <parent link="servo_garra_1"/>
  <child link="Servo_gear_v1_1"/>
  <axis xyz="-0.0 0.0 1.0"/>
</joint>

<joint name="Rev92" type="continuous">
  <origin rpy="0 0 0" xyz="0.0 0.0 0.003"/>
  <parent link="base_link"/>
  <child link="tampa_1"/>
  <axis xyz="-0.0 0.0 1.0"/>
</joint>

</robot>
