<?xml version="1.0" ?>
<robot name="braco_v2" xmlns:xacro="http://www.ros.org/wiki/xacro">

<xacro:include filename="$(find braco_v2_description)/urdf/materials.xacro" />
<xacro:include filename="$(find braco_v2_description)/urdf/braco_v2.trans" />
<xacro:include filename="$(find braco_v2_description)/urdf/braco_v2.gazebo" />
<link name="base_link">
  <inertial>
    <origin rpy="0 0 0" xyz="0.0 4.4408920985006264e-17 0.019999999999999983"/>
    <mass value="0.4404041661434851"/>
    <inertia ixx="0.000423" ixy="0.0" ixz="-0.0" iyy="0.000423" iyz="0.0" izz="0.000728"/>
  </inertial>
  <visual>
    <origin rpy="0 0 0" xyz="0 0 0"/>
    <geometry>
      <mesh filename="package://braco_v2_description/meshes/base_link.stl" scale="0.001 0.001 0.001"/>
    </geometry>
    <material name="silver"/>
  </visual>
  <collision>
    <origin rpy="0 0 0" xyz="0 0 0"/>
    <geometry>
      <mesh filename="package://braco_v2_description/meshes/base_link.stl" scale="0.001 0.001 0.001"/>
    </geometry>
  </collision>
</link>

<link name="Center_arm_v1_1">
  <inertial>
    <origin rpy="0 0 0" xyz="0.014277150157445656 0.009887184158138248 -0.05601557501701446"/>
    <mass value="0.24743903954578314"/>
    <inertia ixx="0.000535" ixy="0.0" ixz="0.000118" iyy="0.000605" iyz="-0.0" izz="0.000106"/>
  </inertial>
  <visual>
    <origin rpy="0 0 0" xyz="-0.142342 0.011691 -0.205954"/>
    <geometry>
      <mesh filename="package://braco_v2_description/meshes/Center_arm_v1_1.stl" scale="0.001 0.001 0.001"/>
    </geometry>
    <material name="silver"/>
  </visual>
  <collision>
    <origin rpy="0 0 0" xyz="-0.142342 0.011691 -0.205954"/>
    <geometry>
      <mesh filename="package://braco_v2_description/meshes/Center_arm_v1_1.stl" scale="0.001 0.001 0.001"/>
    </geometry>
  </collision>
</link>

<link name="Center_arm_bearing_guide_v1_1">
  <inertial>
    <origin rpy="0 0 0" xyz="-0.01039213224987559 0.003221962356880813 0.00600019094374038"/>
    <mass value="0.0033035453927957375"/>
    <inertia ixx="0.0" ixy="0.0" ixz="-0.0" iyy="0.0" iyz="-0.0" izz="0.0"/>
  </inertial>
  <visual>
    <origin rpy="0 0 0" xyz="-0.152734 -0.008309 -0.199954"/>
    <geometry>
      <mesh filename="package://braco_v2_description/meshes/Center_arm_bearing_guide_v1_1.stl" scale="0.001 0.001 0.001"/>
    </geometry>
    <material name="silver"/>
  </visual>
  <collision>
    <origin rpy="0 0 0" xyz="-0.152734 -0.008309 -0.199954"/>
    <geometry>
      <mesh filename="package://braco_v2_description/meshes/Center_arm_bearing_guide_v1_1.stl" scale="0.001 0.001 0.001"/>
    </geometry>
  </collision>
</link>

<link name="Center_arm_bearing_guide_v1__1__1">
  <inertial>
    <origin rpy="0 0 0" xyz="-0.0059998944503106 0.003221962356879297 -0.010392093645181094"/>
    <mass value="0.0033035453927957375"/>
    <inertia ixx="0.0" ixy="0.0" ixz="0.0" iyy="0.0" iyz="0.0" izz="0.0"/>
  </inertial>
  <visual>
    <origin rpy="0 0 0" xyz="-0.178753 -0.008309 -0.10285"/>
    <geometry>
      <mesh filename="package://braco_v2_description/meshes/Center_arm_bearing_guide_v1__1__1.stl" scale="0.001 0.001 0.001"/>
    </geometry>
    <material name="silver"/>
  </visual>
  <collision>
    <origin rpy="0 0 0" xyz="-0.178753 -0.008309 -0.10285"/>
    <geometry>
      <mesh filename="package://braco_v2_description/meshes/Center_arm_bearing_guide_v1__1__1.stl" scale="0.001 0.001 0.001"/>
    </geometry>
  </collision>
</link>

<link name="Center_arm_bearing_guide_clamp_v1_1">
  <inertial>
    <origin rpy="0 0 0" xyz="-1.322497980571491e-07 0.0016578450305448425 1.9094379913320303e-07"/>
    <mass value="0.00026744770959091237"/>
    <inertia ixx="0.0" ixy="-0.0" ixz="0.0" iyy="0.0" iyz="-0.0" izz="0.0"/>
  </inertial>
  <visual>
    <origin rpy="0 0 0" xyz="-0.142342 -0.021709 -0.205954"/>
    <geometry>
      <mesh filename="package://braco_v2_description/meshes/Center_arm_bearing_guide_clamp_v1_1.stl" scale="0.001 0.001 0.001"/>
    </geometry>
    <material name="silver"/>
  </visual>
  <collision>
    <origin rpy="0 0 0" xyz="-0.142342 -0.021709 -0.205954"/>
    <geometry>
      <mesh filename="package://braco_v2_description/meshes/Center_arm_bearing_guide_clamp_v1_1.stl" scale="0.001 0.001 0.001"/>
    </geometry>
  </collision>
</link>

<link name="servo_elbow_1">
  <inertial>
    <origin rpy="0 0 0" xyz="0.15754580602873644 0.20794860786324015 -0.030115300811952045"/>
    <mass value="0.2525786066068201"/>
    <inertia ixx="5.2e-05" ixy="-0.0" ixz="-1.4e-05" iyy="4.4e-05" iyz="-0.0" izz="5.7e-05"/>
  </inertial>
  <visual>
    <origin rpy="0 0 0" xyz="0.022846 0.244866 -0.229657"/>
    <geometry>
      <mesh filename="package://braco_v2_description/meshes/servo_elbow_1.stl" scale="0.001 0.001 0.001"/>
    </geometry>
    <material name="silver"/>
  </visual>
  <collision>
    <origin rpy="0 0 0" xyz="0.022846 0.244866 -0.229657"/>
    <geometry>
      <mesh filename="package://braco_v2_description/meshes/servo_elbow_1.stl" scale="0.001 0.001 0.001"/>
    </geometry>
  </collision>
</link>

<link name="servo_punho_rot_1">
  <inertial>
    <origin rpy="0 0 0" xyz="0.14034378523693494 -0.10986496796742812 -0.22086481094673482"/>
    <mass value="0.25257832542625036"/>
    <inertia ixx="4.4e-05" ixy="-0.0" ixz="1e-06" iyy="6.8e-05" iyz="0.0" izz="4.1e-05"/>
  </inertial>
  <visual>
    <origin rpy="0 0 0" xyz="-0.093832 -0.110262 -0.322983"/>
    <geometry>
      <mesh filename="package://braco_v2_description/meshes/servo_punho_rot_1.stl" scale="0.001 0.001 0.001"/>
    </geometry>
    <material name="silver"/>
  </visual>
  <collision>
    <origin rpy="0 0 0" xyz="-0.093832 -0.110262 -0.322983"/>
    <geometry>
      <mesh filename="package://braco_v2_description/meshes/servo_punho_rot_1.stl" scale="0.001 0.001 0.001"/>
    </geometry>
  </collision>
</link>

<link name="servo_punho_xy_1">
  <inertial>
    <origin rpy="0 0 0" xyz="0.009976146320704926 -0.02522641850043935 -6.558513723775583e-08"/>
    <mass value="0.25257832542625036"/>
    <inertia ixx="4.1e-05" ixy="1e-06" ixz="0.0" iyy="4.4e-05" iyz="-0.0" izz="6.8e-05"/>
  </inertial>
  <visual>
    <origin rpy="0 0 0" xyz="-0.172753 0.011691 -0.092458"/>
    <geometry>
      <mesh filename="package://braco_v2_description/meshes/servo_punho_xy_1.stl" scale="0.001 0.001 0.001"/>
    </geometry>
    <material name="silver"/>
  </visual>
  <collision>
    <origin rpy="0 0 0" xyz="-0.172753 0.011691 -0.092458"/>
    <geometry>
      <mesh filename="package://braco_v2_description/meshes/servo_punho_xy_1.stl" scale="0.001 0.001 0.001"/>
    </geometry>
  </collision>
</link>

<link name="punho_1">
  <inertial>
    <origin rpy="0 0 0" xyz="-0.1328033049390942 0.12072689824420818 0.028960027873234748"/>
    <mass value="0.21880690583277723"/>
    <inertia ixx="0.000235" ixy="1.1e-05" ixz="-7e-06" iyy="0.000273" iyz="0.0" izz="0.000371"/>
  </inertial>
  <visual>
    <origin rpy="0 0 0" xyz="-0.342104 0.118081 -0.064457"/>
    <geometry>
      <mesh filename="package://braco_v2_description/meshes/punho_1.stl" scale="0.001 0.001 0.001"/>
    </geometry>
    <material name="silver"/>
  </visual>
  <collision>
    <origin rpy="0 0 0" xyz="-0.342104 0.118081 -0.064457"/>
    <geometry>
      <mesh filename="package://braco_v2_description/meshes/punho_1.stl" scale="0.001 0.001 0.001"/>
    </geometry>
  </collision>
</link>

<link name="Center_arm_bearing_guide_clamp_v1_punho_1">
  <inertial>
    <origin rpy="0 0 0" xyz="1.05549629869639e-07 0.0016578450305445892 -9.36450987448767e-08"/>
    <mass value="0.00026744770959091237"/>
    <inertia ixx="0.0" ixy="0.0" ixz="-0.0" iyy="0.0" iyz="-0.0" izz="0.0"/>
  </inertial>
  <visual>
    <origin rpy="0 0 0" xyz="-0.172753 -0.021709 -0.092458"/>
    <geometry>
      <mesh filename="package://braco_v2_description/meshes/Center_arm_bearing_guide_clamp_v1_punho_1.stl" scale="0.001 0.001 0.001"/>
    </geometry>
    <material name="silver"/>
  </visual>
  <collision>
    <origin rpy="0 0 0" xyz="-0.172753 -0.021709 -0.092458"/>
    <geometry>
      <mesh filename="package://braco_v2_description/meshes/Center_arm_bearing_guide_clamp_v1_punho_1.stl" scale="0.001 0.001 0.001"/>
    </geometry>
  </collision>
</link>

<link name="corpo_garra_1">
  <inertial>
    <origin rpy="0 0 0" xyz="0.03690104485756707 3.972525702432197e-09 -0.004369986373359419"/>
    <mass value="0.0475742677792808"/>
    <inertia ixx="2e-05" ixy="-0.0" ixz="2e-06" iyy="5.2e-05" iyz="0.0" izz="4.3e-05"/>
  </inertial>
  <visual>
    <origin rpy="0 0 0" xyz="-0.259402 -0.000397 -0.092142"/>
    <geometry>
      <mesh filename="package://braco_v2_description/meshes/corpo_garra_1.stl" scale="0.001 0.001 0.001"/>
    </geometry>
    <material name="silver"/>
  </visual>
  <collision>
    <origin rpy="0 0 0" xyz="-0.259402 -0.000397 -0.092142"/>
    <geometry>
      <mesh filename="package://braco_v2_description/meshes/corpo_garra_1.stl" scale="0.001 0.001 0.001"/>
    </geometry>
  </collision>
</link>

<link name="Bearing_guide_v1_1">
  <inertial>
    <origin rpy="0 0 0" xyz="4.6121928154452263e-07 3.97206351886387e-09 0.01725014828221419"/>
    <mass value="0.0016815613439380714"/>
    <inertia ixx="0.0" ixy="0.0" ixz="-0.0" iyy="0.0" iyz="-0.0" izz="0.0"/>
  </inertial>
  <visual>
    <origin rpy="0 0 0" xyz="-0.334152 -0.000397 -0.074892"/>
    <geometry>
      <mesh filename="package://braco_v2_description/meshes/Bearing_guide_v1_1.stl" scale="0.001 0.001 0.001"/>
    </geometry>
    <material name="silver"/>
  </visual>
  <collision>
    <origin rpy="0 0 0" xyz="-0.334152 -0.000397 -0.074892"/>
    <geometry>
      <mesh filename="package://braco_v2_description/meshes/Bearing_guide_v1_1.stl" scale="0.001 0.001 0.001"/>
    </geometry>
  </collision>
</link>

<link name="Bearing_top-bottom_bushing_v1_1">
  <inertial>
    <origin rpy="0 0 0" xyz="4.6121928093389997e-07 3.972462620622456e-09 -0.001749851717786216"/>
    <mass value="0.0016106179771745465"/>
    <inertia ixx="0.0" ixy="0.0" ixz="0.0" iyy="0.0" iyz="-0.0" izz="0.0"/>
  </inertial>
  <visual>
    <origin rpy="0 0 0" xyz="-0.334152 -0.000397 -0.104392"/>
    <geometry>
      <mesh filename="package://braco_v2_description/meshes/Bearing_top-bottom_bushing_v1_1.stl" scale="0.001 0.001 0.001"/>
    </geometry>
    <material name="silver"/>
  </visual>
  <collision>
    <origin rpy="0 0 0" xyz="-0.334152 -0.000397 -0.104392"/>
    <geometry>
      <mesh filename="package://braco_v2_description/meshes/Bearing_top-bottom_bushing_v1_1.stl" scale="0.001 0.001 0.001"/>
    </geometry>
  </collision>
</link>

<link name="Bearing_top-bottom_bushing_v1__1__1">
  <inertial>
    <origin rpy="0 0 0" xyz="4.612192812114557e-07 3.9724627058407465e-09 0.0017501482822140368"/>
    <mass value="0.0016106179771745465"/>
    <inertia ixx="0.0" ixy="0.0" ixz="0.0" iyy="0.0" iyz="-0.0" izz="0.0"/>
  </inertial>
  <visual>
    <origin rpy="0 0 0" xyz="-0.334152 -0.000397 -0.079892"/>
    <geometry>
      <mesh filename="package://braco_v2_description/meshes/Bearing_top-bottom_bushing_v1__1__1.stl" scale="0.001 0.001 0.001"/>
    </geometry>
    <material name="silver"/>
  </visual>
  <collision>
    <origin rpy="0 0 0" xyz="-0.334152 -0.000397 -0.079892"/>
    <geometry>
      <mesh filename="package://braco_v2_description/meshes/Bearing_top-bottom_bushing_v1__1__1.stl" scale="0.001 0.001 0.001"/>
    </geometry>
  </collision>
</link>

<link name="Bearing_center_bushing_v1_1">
  <inertial>
    <origin rpy="0 0 0" xyz="0.09827446121928143 0.04192300397246268 0.11753614828221406"/>
    <mass value="0.0034513242368025996"/>
    <inertia ixx="0.0" ixy="0.0" ixz="0.0" iyy="0.0" iyz="-0.0" izz="0.0"/>
  </inertial>
  <visual>
    <origin rpy="0 0 0" xyz="-0.235878 0.041526 0.025394"/>
    <geometry>
      <mesh filename="package://braco_v2_description/meshes/Bearing_center_bushing_v1_1.stl" scale="0.001 0.001 0.001"/>
    </geometry>
    <material name="silver"/>
  </visual>
  <collision>
    <origin rpy="0 0 0" xyz="-0.235878 0.041526 0.025394"/>
    <geometry>
      <mesh filename="package://braco_v2_description/meshes/Bearing_center_bushing_v1_1.stl" scale="0.001 0.001 0.001"/>
    </geometry>
  </collision>
</link>

<link name="servo_garra_1">
  <inertial>
    <origin rpy="0 0 0" xyz="0.053330533392260265 -0.018574770578143565 0.08636947229986802"/>
    <mass value="0.25257832542625036"/>
    <inertia ixx="4.1e-05" ixy="-0.0" ixz="1e-06" iyy="6.8e-05" iyz="0.0" izz="4.4e-05"/>
  </inertial>
  <visual>
    <origin rpy="0 0 0" xyz="-0.245878 -0.018974 0.025394"/>
    <geometry>
      <mesh filename="package://braco_v2_description/meshes/servo_garra_1.stl" scale="0.001 0.001 0.001"/>
    </geometry>
    <material name="silver"/>
  </visual>
  <collision>
    <origin rpy="0 0 0" xyz="-0.245878 -0.018974 0.025394"/>
    <geometry>
      <mesh filename="package://braco_v2_description/meshes/servo_garra_1.stl" scale="0.001 0.001 0.001"/>
    </geometry>
  </collision>
</link>

<link name="Gripper_120T_v1_1">
  <inertial>
    <origin rpy="0 0 0" xyz="0.010502843706276688 0.0181735244198357 0.006028625191617287"/>
    <mass value="0.031315152970389164"/>
    <inertia ixx="1e-05" ixy="-4e-06" ixz="-3e-06" iyy="4e-05" iyz="-0.0" izz="4.8e-05"/>
  </inertial>
  <visual>
    <origin rpy="0 0 0" xyz="-0.334152 -0.000397 -0.083392"/>
    <geometry>
      <mesh filename="package://braco_v2_description/meshes/Gripper_120T_v1_1.stl" scale="0.001 0.001 0.001"/>
    </geometry>
    <material name="silver"/>
  </visual>
  <collision>
    <origin rpy="0 0 0" xyz="-0.334152 -0.000397 -0.083392"/>
    <geometry>
      <mesh filename="package://braco_v2_description/meshes/Gripper_120T_v1_1.stl" scale="0.001 0.001 0.001"/>
    </geometry>
  </collision>
</link>

<link name="Gripper_72T_v1_1">
  <inertial>
    <origin rpy="0 0 0" xyz="0.020484421154321197 -0.01768686032720145 -0.0012214830647412217"/>
    <mass value="0.0250024753894087"/>
    <inertia ixx="4e-06" ixy="2e-06" ixz="2e-06" iyy="2e-05" iyz="-0.0" izz="2.2e-05"/>
  </inertial>
  <visual>
    <origin rpy="0 0 0" xyz="-0.334152 -0.000397 -0.095892"/>
    <geometry>
      <mesh filename="package://braco_v2_description/meshes/Gripper_72T_v1_1.stl" scale="0.001 0.001 0.001"/>
    </geometry>
    <material name="silver"/>
  </visual>
  <collision>
    <origin rpy="0 0 0" xyz="-0.334152 -0.000397 -0.095892"/>
    <geometry>
      <mesh filename="package://braco_v2_description/meshes/Gripper_72T_v1_1.stl" scale="0.001 0.001 0.001"/>
    </geometry>
  </collision>
</link>

<link name="Servo_gear_v1_1">
  <inertial>
    <origin rpy="0 0 0" xyz="4.926212099354288e-07 2.574818621269492e-07 0.0043180267545464834"/>
    <mass value="0.010154744217590462"/>
    <inertia ixx="1e-06" ixy="0.0" ixz="0.0" iyy="1e-06" iyz="0.0" izz="1e-06"/>
  </inertial>
  <visual>
    <origin rpy="0 0 0" xyz="-0.289232 -0.000399 -0.086202"/>
    <geometry>
      <mesh filename="package://braco_v2_description/meshes/Servo_gear_v1_1.stl" scale="0.001 0.001 0.001"/>
    </geometry>
    <material name="silver"/>
  </visual>
  <collision>
    <origin rpy="0 0 0" xyz="-0.289232 -0.000399 -0.086202"/>
    <geometry>
      <mesh filename="package://braco_v2_description/meshes/Servo_gear_v1_1.stl" scale="0.001 0.001 0.001"/>
    </geometry>
  </collision>
</link>

<link name="servo_right_1">
  <inertial>
    <origin rpy="0 0 0" xyz="0.045095727044045304 0.0126085814995585 0.08368692782702274"/>
    <mass value="0.25257832542625036"/>
    <inertia ixx="6.8e-05" ixy="-0.0" ixz="-0.0" iyy="4.4e-05" iyz="-1e-06" izz="4.1e-05"/>
  </inertial>
  <visual>
    <origin rpy="0 0 0" xyz="0.043653 0.060836 0.007493"/>
    <geometry>
      <mesh filename="package://braco_v2_description/meshes/servo_right_1.stl" scale="0.001 0.001 0.001"/>
    </geometry>
    <material name="silver"/>
  </visual>
  <collision>
    <origin rpy="0 0 0" xyz="0.043653 0.060836 0.007493"/>
    <geometry>
      <mesh filename="package://braco_v2_description/meshes/servo_right_1.stl" scale="0.001 0.001 0.001"/>
    </geometry>
  </collision>
</link>

<link name="ombro_1">
  <inertial>
    <origin rpy="0 0 0" xyz="0.07104948639429079 0.02440644138217429 0.060376060535231424"/>
    <mass value="0.488316525379642"/>
    <inertia ixx="0.00123" ixy="-2.9e-05" ixz="-0.000812" iyy="0.001965" iyz="-2.5e-05" izz="0.001495"/>
  </inertial>
  <visual>
    <origin rpy="0 0 0" xyz="-0.001443 0.023001 -0.08617"/>
    <geometry>
      <mesh filename="package://braco_v2_description/meshes/ombro_1.stl" scale="0.001 0.001 0.001"/>
    </geometry>
    <material name="silver"/>
  </visual>
  <collision>
    <origin rpy="0 0 0" xyz="-0.001443 0.023001 -0.08617"/>
    <geometry>
      <mesh filename="package://braco_v2_description/meshes/ombro_1.stl" scale="0.001 0.001 0.001"/>
    </geometry>
  </collision>
</link>

<link name="tampa_1">
  <inertial>
    <origin rpy="0 0 0" xyz="0.0011216189485683523 0.004916751779089888 0.03437462699193116"/>
    <mass value="0.1480855028648141"/>
    <inertia ixx="0.000274" ixy="-0.0" ixz="-2e-06" iyy="0.00016" iyz="-1e-06" izz="0.000246"/>
  </inertial>
  <visual>
    <origin rpy="0 0 0" xyz="-0.0 0.0 -0.04"/>
    <geometry>
      <mesh filename="package://braco_v2_description/meshes/tampa_1.stl" scale="0.001 0.001 0.001"/>
    </geometry>
    <material name="silver"/>
  </visual>
  <collision>
    <origin rpy="0 0 0" xyz="-0.0 0.0 -0.04"/>
    <geometry>
      <mesh filename="package://braco_v2_description/meshes/tampa_1.stl" scale="0.001 0.001 0.001"/>
    </geometry>
  </collision>
</link>

<joint name="Rev52" type="continuous">
  <origin rpy="0 0 0" xyz="0.165188 0.233175 -0.023703"/>
  <parent link="servo_elbow_1"/>
  <child link="Center_arm_v1_1"/>
  <axis xyz="0.0 1.0 0.0"/>
</joint>

<joint name="Rigid54" type="fixed">
  <origin rpy="0 0 0" xyz="0.010392 0.02 -0.006"/>
  <parent link="Center_arm_v1_1"/>
  <child link="Center_arm_bearing_guide_v1_1"/>
</joint>

<joint name="Rigid56" type="fixed">
  <origin rpy="0 0 0" xyz="0.036411 0.02 -0.103104"/>
  <parent link="Center_arm_v1_1"/>
  <child link="Center_arm_bearing_guide_v1__1__1"/>
</joint>

<joint name="Rigid58" type="fixed">
  <origin rpy="0 0 0" xyz="-0.010392 0.0134 0.006"/>
  <parent link="Center_arm_bearing_guide_v1_1"/>
  <child link="Center_arm_bearing_guide_clamp_v1_1"/>
</joint>

<joint name="Rigid65" type="fixed">
  <origin rpy="0 0 0" xyz="-0.024289 -0.221865 0.143487"/>
  <parent link="ombro_1"/>
  <child link="servo_elbow_1"/>
</joint>

<joint name="Rigid70" type="fixed">
  <origin rpy="0 0 0" xyz="-0.248272 0.228343 0.258526"/>
  <parent link="punho_1"/>
  <child link="servo_punho_rot_1"/>
</joint>

<joint name="Rev71" type="continuous">
  <origin rpy="0 0 0" xyz="0.030411 0.0 -0.113496"/>
  <parent link="Center_arm_v1_1"/>
  <child link="servo_punho_xy_1"/>
  <axis xyz="-0.0 -1.0 -0.0"/>
</joint>

<joint name="Rigid72" type="fixed">
  <origin rpy="0 0 0" xyz="0.169351 -0.10639 -0.028001"/>
  <parent link="servo_punho_xy_1"/>
  <child link="punho_1"/>
</joint>

<joint name="Rigid74" type="fixed">
  <origin rpy="0 0 0" xyz="-0.006 0.0134 -0.010392"/>
  <parent link="Center_arm_bearing_guide_v1__1__1"/>
  <child link="Center_arm_bearing_guide_clamp_v1_punho_1"/>
</joint>

<joint name="Rev81" type="continuous">
  <origin rpy="0 0 0" xyz="0.16557 -0.109865 -0.230841"/>
  <parent link="servo_punho_rot_1"/>
  <child link="corpo_garra_1"/>
  <axis xyz="1.0 0.0 -0.0"/>
</joint>

<joint name="Rigid82" type="fixed">
  <origin rpy="0 0 0" xyz="0.07475 0.0 -0.01725"/>
  <parent link="corpo_garra_1"/>
  <child link="Bearing_guide_v1_1"/>
</joint>

<joint name="Rigid83" type="fixed">
  <origin rpy="0 0 0" xyz="0.07475 0.0 0.01225"/>
  <parent link="corpo_garra_1"/>
  <child link="Bearing_top-bottom_bushing_v1_1"/>
</joint>

<joint name="Rigid84" type="fixed">
  <origin rpy="0 0 0" xyz="0.07475 0.0 -0.01225"/>
  <parent link="corpo_garra_1"/>
  <child link="Bearing_top-bottom_bushing_v1__1__1"/>
</joint>

<joint name="Rigid85" type="fixed">
  <origin rpy="0 0 0" xyz="-0.023524 -0.041923 -0.117536"/>
  <parent link="corpo_garra_1"/>
  <child link="Bearing_center_bushing_v1_1"/>
</joint>

<joint name="Rigid86" type="fixed">
  <origin rpy="0 0 0" xyz="-0.013524 0.018577 -0.117536"/>
  <parent link="corpo_garra_1"/>
  <child link="servo_garra_1"/>
</joint>

<joint name="Rev87" type="revolute">
  <origin rpy="0 0 0" xyz="0.0 0.0 0.0035"/>
  <parent link="Bearing_top-bottom_bushing_v1__1__1"/>
  <child link="Gripper_120T_v1_1"/>
  <axis xyz="0.0 -0.0 1.0"/>
  <limit effort="100" lower="0.0" upper="0.785398" velocity="100"/>
</joint>

<joint name="Rev88" type="revolute">
  <origin rpy="0 0 0" xyz="0.098274 0.041923 0.121286"/>
  <parent link="Bearing_center_bushing_v1_1"/>
  <child link="Gripper_72T_v1_1"/>
  <axis xyz="0.0 -0.0 1.0"/>
  <limit effort="100" lower="-0.785398" upper="0.0" velocity="100"/>
</joint>

<joint name="Rev89" type="continuous">
  <origin rpy="0 0 0" xyz="0.043354 -0.018575 0.111596"/>
  <parent link="servo_garra_1"/>
  <child link="Servo_gear_v1_1"/>
  <axis xyz="0.0 -0.0 1.0"/>
</joint>

<joint name="Rigid94" type="fixed">
  <origin rpy="0 0 0" xyz="-0.043653 -0.060836 -0.047493"/>
  <parent link="tampa_1"/>
  <child link="servo_right_1"/>
</joint>

<joint name="Rev95" type="continuous">
  <origin rpy="0 0 0" xyz="0.045096 0.037835 0.093663"/>
  <parent link="servo_right_1"/>
  <child link="ombro_1"/>
  <axis xyz="0.0 1.0 0.0"/>
</joint>

<joint name="Rev96" type="continuous">
  <origin rpy="0 0 0" xyz="0.0 0.0 0.04"/>
  <parent link="base_link"/>
  <child link="tampa_1"/>
  <axis xyz="0.0 0.0 1.0"/>
</joint>

</robot>
