<?xml version="1.0" ?>
<robot name="braco_v2" xmlns:xacro="http://www.ros.org/wiki/xacro">

<xacro:include filename="$(find braco_v2_description)/urdf/materials.xacro" />
<xacro:include filename="$(find braco_v2_description)/urdf/braco_v2.trans" />
<xacro:include filename="$(find braco_v2_description)/urdf/braco_v2.gazebo" />
<link name="base_link">
  <inertial>
    <origin rpy="0 0 0" xyz="0.0 4.884981308350689e-17 0.019999999999999983"/>
    <mass value="0.4404041661434851"/>
    <inertia ixx="0.000423" ixy="0.0" ixz="-0.0" iyy="0.000423" iyz="0.0" izz="0.000728"/>
  </inertial>
  <visual>
    <origin rpy="0 0 0" xyz="0 0 0"/>
    <geometry>
      <mesh filename="package://braco_v2_description/meshes/base_link.stl" scale="0.001 0.001 0.001"/>
    </geometry>
    <material name="silver"/>
  </visual>
  <collision>
    <origin rpy="0 0 0" xyz="0 0 0"/>
    <geometry>
      <mesh filename="package://braco_v2_description/meshes/base_link.stl" scale="0.001 0.001 0.001"/>
    </geometry>
  </collision>
</link>

<link name="servo_left_1">
  <inertial>
    <origin rpy="0 0 0" xyz="-0.0014473150385015167 0.11316693346425025 -0.006915072172978931"/>
    <mass value="0.25257832542625036"/>
    <inertia ixx="6.8e-05" ixy="-0.0" ixz="0.0" iyy="4.4e-05" iyz="1e-06" izz="4.1e-05"/>
  </inertial>
  <visual>
    <origin rpy="0 0 0" xyz="-0.002899 0.064141 -0.083109"/>
    <geometry>
      <mesh filename="package://braco_v2_description/meshes/servo_left_1.stl" scale="0.001 0.001 0.001"/>
    </geometry>
    <material name="silver"/>
  </visual>
  <collision>
    <origin rpy="0 0 0" xyz="-0.002899 0.064141 -0.083109"/>
    <geometry>
      <mesh filename="package://braco_v2_description/meshes/servo_left_1.stl" scale="0.001 0.001 0.001"/>
    </geometry>
  </collision>
</link>

<link name="servo_right_1">
  <inertial>
    <origin rpy="0 0 0" xyz="0.06544272704404532 -0.11316641850044139 0.07250492782702289"/>
    <mass value="0.25257832542625036"/>
    <inertia ixx="6.8e-05" ixy="-0.0" ixz="-0.0" iyy="4.4e-05" iyz="-1e-06" izz="4.1e-05"/>
  </inertial>
  <visual>
    <origin rpy="0 0 0" xyz="0.064 -0.064939 -0.003689"/>
    <geometry>
      <mesh filename="package://braco_v2_description/meshes/servo_right_1.stl" scale="0.001 0.001 0.001"/>
    </geometry>
    <material name="silver"/>
  </visual>
  <collision>
    <origin rpy="0 0 0" xyz="0.064 -0.064939 -0.003689"/>
    <geometry>
      <mesh filename="package://braco_v2_description/meshes/servo_right_1.stl" scale="0.001 0.001 0.001"/>
    </geometry>
  </collision>
</link>

<link name="Center_arm_v1_1">
  <inertial>
    <origin rpy="0 0 0" xyz="-0.0007068682064798326 0.00988718415813914 -0.057802053392263145"/>
    <mass value="0.24743903954578314"/>
    <inertia ixx="0.000566" ixy="0.0" ixz="-5e-06" iyy="0.000605" iyz="-0.0" izz="7.6e-05"/>
  </inertial>
  <visual>
    <origin rpy="0 0 0" xyz="-0.168543 0.011691 -0.165405"/>
    <geometry>
      <mesh filename="package://braco_v2_description/meshes/Center_arm_v1_1.stl" scale="0.001 0.001 0.001"/>
    </geometry>
    <material name="silver"/>
  </visual>
  <collision>
    <origin rpy="0 0 0" xyz="-0.168543 0.011691 -0.165405"/>
    <geometry>
      <mesh filename="package://braco_v2_description/meshes/Center_arm_v1_1.stl" scale="0.001 0.001 0.001"/>
    </geometry>
  </collision>
</link>

<link name="Center_arm_bearing_guide_v1_1">
  <inertial>
    <origin rpy="0 0 0" xyz="-0.008485716956285222 0.0032219623568818436 0.00848525422791585"/>
    <mass value="0.0033035453927957375"/>
    <inertia ixx="0.0" ixy="-0.0" ixz="0.0" iyy="0.0" iyz="-0.0" izz="0.0"/>
  </inertial>
  <visual>
    <origin rpy="0 0 0" xyz="-0.177029 -0.008309 -0.15692"/>
    <geometry>
      <mesh filename="package://braco_v2_description/meshes/Center_arm_bearing_guide_v1_1.stl" scale="0.001 0.001 0.001"/>
    </geometry>
    <material name="silver"/>
  </visual>
  <collision>
    <origin rpy="0 0 0" xyz="-0.177029 -0.008309 -0.15692"/>
    <geometry>
      <mesh filename="package://braco_v2_description/meshes/Center_arm_bearing_guide_v1_1.stl" scale="0.001 0.001 0.001"/>
    </geometry>
  </collision>
</link>

<link name="Center_arm_bearing_guide_v1__1__1">
  <inertial>
    <origin rpy="0 0 0" xyz="-0.00848571695625569 0.0032219623568800256 -0.008485745772046513"/>
    <mass value="0.0033035453927957375"/>
    <inertia ixx="0.0" ixy="0.0" ixz="0.0" iyy="0.0" iyz="0.0" izz="0.0"/>
  </inertial>
  <visual>
    <origin rpy="0 0 0" xyz="-0.177029 -0.008309 -0.056391"/>
    <geometry>
      <mesh filename="package://braco_v2_description/meshes/Center_arm_bearing_guide_v1__1__1.stl" scale="0.001 0.001 0.001"/>
    </geometry>
    <material name="silver"/>
  </visual>
  <collision>
    <origin rpy="0 0 0" xyz="-0.177029 -0.008309 -0.056391"/>
    <geometry>
      <mesh filename="package://braco_v2_description/meshes/Center_arm_bearing_guide_v1__1__1.stl" scale="0.001 0.001 0.001"/>
    </geometry>
  </collision>
</link>

<link name="Center_arm_bearing_guide_clamp_v1_1">
  <inertial>
    <origin rpy="0 0 0" xyz="2.830438048384565e-07 0.001657845030545873 2.542279526063229e-07"/>
    <mass value="0.00026744770959091237"/>
    <inertia ixx="0.0" ixy="-0.0" ixz="0.0" iyy="0.0" iyz="0.0" izz="0.0"/>
  </inertial>
  <visual>
    <origin rpy="0 0 0" xyz="-0.168543 -0.021709 -0.165405"/>
    <geometry>
      <mesh filename="package://braco_v2_description/meshes/Center_arm_bearing_guide_clamp_v1_1.stl" scale="0.001 0.001 0.001"/>
    </geometry>
    <material name="silver"/>
  </visual>
  <collision>
    <origin rpy="0 0 0" xyz="-0.168543 -0.021709 -0.165405"/>
    <geometry>
      <mesh filename="package://braco_v2_description/meshes/Center_arm_bearing_guide_clamp_v1_1.stl" scale="0.001 0.001 0.001"/>
    </geometry>
  </collision>
</link>

<link name="ombro_1">
  <inertial>
    <origin rpy="0 0 0" xyz="0.08425500605814476 0.024406441382175105 0.03992975695830678"/>
    <mass value="0.488316525379642"/>
    <inertia ixx="0.000841" ixy="-3.4e-05" ixz="-0.000637" iyy="0.001965" iyz="-1.6e-05" izz="0.001884"/>
  </inertial>
  <visual>
    <origin rpy="0 0 0" xyz="-0.001443 0.023001 -0.08617"/>
    <geometry>
      <mesh filename="package://braco_v2_description/meshes/ombro_1.stl" scale="0.001 0.001 0.001"/>
    </geometry>
    <material name="silver"/>
  </visual>
  <collision>
    <origin rpy="0 0 0" xyz="-0.001443 0.023001 -0.08617"/>
    <geometry>
      <mesh filename="package://braco_v2_description/meshes/ombro_1.stl" scale="0.001 0.001 0.001"/>
    </geometry>
  </collision>
</link>

<link name="servo_elbow_1">
  <inertial>
    <origin rpy="0 0 0" xyz="0.11594994326799513 0.20794860786324115 -0.025841826052428907"/>
    <mass value="0.2525786066068201"/>
    <inertia ixx="4.6e-05" ixy="-0.0" ixz="-1.1e-05" iyy="4.4e-05" iyz="-0.0" izz="6.3e-05"/>
  </inertial>
  <visual>
    <origin rpy="0 0 0" xyz="-0.043552 0.244866 -0.187031"/>
    <geometry>
      <mesh filename="package://braco_v2_description/meshes/servo_elbow_1.stl" scale="0.001 0.001 0.001"/>
    </geometry>
    <material name="silver"/>
  </visual>
  <collision>
    <origin rpy="0 0 0" xyz="-0.043552 0.244866 -0.187031"/>
    <geometry>
      <mesh filename="package://braco_v2_description/meshes/servo_elbow_1.stl" scale="0.001 0.001 0.001"/>
    </geometry>
  </collision>
</link>

<link name="servo_punho_rot_1">
  <inertial>
    <origin rpy="0 0 0" xyz="0.09579196273098822 -0.10986496796742722 -0.2166544630735875"/>
    <mass value="0.25257832542625036"/>
    <inertia ixx="4.4e-05" ixy="-0.0" ixz="1e-06" iyy="6.8e-05" iyz="0.0" izz="4.1e-05"/>
  </inertial>
  <visual>
    <origin rpy="0 0 0" xyz="-0.134174 -0.110262 -0.27422"/>
    <geometry>
      <mesh filename="package://braco_v2_description/meshes/servo_punho_rot_1.stl" scale="0.001 0.001 0.001"/>
    </geometry>
    <material name="silver"/>
  </visual>
  <collision>
    <origin rpy="0 0 0" xyz="-0.134174 -0.110262 -0.27422"/>
    <geometry>
      <mesh filename="package://braco_v2_description/meshes/servo_punho_rot_1.stl" scale="0.001 0.001 0.001"/>
    </geometry>
  </collision>
</link>

<link name="servo_punho_xy_1">
  <inertial>
    <origin rpy="0 0 0" xyz="0.009976323814758298 -0.025226418500438705 2.8228800989793523e-07"/>
    <mass value="0.25257832542625036"/>
    <inertia ixx="4.1e-05" ixy="1e-06" ixz="0.0" iyy="4.4e-05" iyz="-0.0" izz="6.8e-05"/>
  </inertial>
  <visual>
    <origin rpy="0 0 0" xyz="-0.168543 0.011691 -0.047905"/>
    <geometry>
      <mesh filename="package://braco_v2_description/meshes/servo_punho_xy_1.stl" scale="0.001 0.001 0.001"/>
    </geometry>
    <material name="silver"/>
  </visual>
  <collision>
    <origin rpy="0 0 0" xyz="-0.168543 0.011691 -0.047905"/>
    <geometry>
      <mesh filename="package://braco_v2_description/meshes/servo_punho_xy_1.stl" scale="0.001 0.001 0.001"/>
    </geometry>
  </collision>
</link>

<link name="punho_1">
  <inertial>
    <origin rpy="0 0 0" xyz="-0.12859312744504092 0.07617389824420893 0.028959375746381744"/>
    <mass value="0.21880690583277723"/>
    <inertia ixx="0.000235" ixy="1.1e-05" ixz="-7e-06" iyy="0.000273" iyz="0.0" izz="0.000371"/>
  </inertial>
  <visual>
    <origin rpy="0 0 0" xyz="-0.333684 0.073528 -0.019905"/>
    <geometry>
      <mesh filename="package://braco_v2_description/meshes/punho_1.stl" scale="0.001 0.001 0.001"/>
    </geometry>
    <material name="silver"/>
  </visual>
  <collision>
    <origin rpy="0 0 0" xyz="-0.333684 0.073528 -0.019905"/>
    <geometry>
      <mesh filename="package://braco_v2_description/meshes/punho_1.stl" scale="0.001 0.001 0.001"/>
    </geometry>
  </collision>
</link>

<link name="Center_arm_bearing_guide_clamp_v1_punho_1">
  <inertial>
    <origin rpy="0 0 0" xyz="2.8304370813803104e-07 0.0016578450305453248 2.5422804841163105e-07"/>
    <mass value="0.00026744770959091237"/>
    <inertia ixx="0.0" ixy="0.0" ixz="-0.0" iyy="0.0" iyz="-0.0" izz="0.0"/>
  </inertial>
  <visual>
    <origin rpy="0 0 0" xyz="-0.168543 -0.021709 -0.047905"/>
    <geometry>
      <mesh filename="package://braco_v2_description/meshes/Center_arm_bearing_guide_clamp_v1_punho_1.stl" scale="0.001 0.001 0.001"/>
    </geometry>
    <material name="silver"/>
  </visual>
  <collision>
    <origin rpy="0 0 0" xyz="-0.168543 -0.021709 -0.047905"/>
    <geometry>
      <mesh filename="package://braco_v2_description/meshes/Center_arm_bearing_guide_clamp_v1_punho_1.stl" scale="0.001 0.001 0.001"/>
    </geometry>
  </collision>
</link>

<link name="Base_servo_mount_left_1">
  <inertial>
    <origin rpy="0 0 0" xyz="-0.01587454048783789 0.00020637077105208762 0.04245293340657498"/>
    <mass value="0.04710420541299449"/>
    <inertia ixx="2.1e-05" ixy="0.0" ixz="0.0" iyy="3.9e-05" iyz="0.0" izz="2e-05"/>
  </inertial>
  <visual>
    <origin rpy="0 0 0" xyz="-0.017324 -0.037609 -0.043"/>
    <geometry>
      <mesh filename="package://braco_v2_description/meshes/Base_servo_mount_left_1.stl" scale="0.001 0.001 0.001"/>
    </geometry>
    <material name="silver"/>
  </visual>
  <collision>
    <origin rpy="0 0 0" xyz="-0.017324 -0.037609 -0.043"/>
    <geometry>
      <mesh filename="package://braco_v2_description/meshes/Base_servo_mount_left_1.stl" scale="0.001 0.001 0.001"/>
    </geometry>
  </collision>
</link>

<link name="Base_servo_mount_right_v1_1">
  <inertial>
    <origin rpy="0 0 0" xyz="-0.015875047506617307 -0.0002058558072429162 0.0424529334065758"/>
    <mass value="0.04710420541299451"/>
    <inertia ixx="2.1e-05" ixy="-0.0" ixz="-0.0" iyy="3.9e-05" iyz="-0.0" izz="2e-05"/>
  </inertial>
  <visual>
    <origin rpy="0 0 0" xyz="-0.01732 0.036811 -0.043"/>
    <geometry>
      <mesh filename="package://braco_v2_description/meshes/Base_servo_mount_right_v1_1.stl" scale="0.001 0.001 0.001"/>
    </geometry>
    <material name="silver"/>
  </visual>
  <collision>
    <origin rpy="0 0 0" xyz="-0.01732 0.036811 -0.043"/>
    <geometry>
      <mesh filename="package://braco_v2_description/meshes/Base_servo_mount_right_v1_1.stl" scale="0.001 0.001 0.001"/>
    </geometry>
  </collision>
</link>

<link name="corpo_garra_1">
  <inertial>
    <origin rpy="0 0 0" xyz="0.036900222351620215 3.972526661625859e-09 -0.0043696385002113605"/>
    <mass value="0.0475742677792808"/>
    <inertia ixx="2e-05" ixy="-0.0" ixz="2e-06" iyy="5.2e-05" iyz="0.0" izz="4.3e-05"/>
  </inertial>
  <visual>
    <origin rpy="0 0 0" xyz="-0.255193 -0.000397 -0.047589"/>
    <geometry>
      <mesh filename="package://braco_v2_description/meshes/corpo_garra_1.stl" scale="0.001 0.001 0.001"/>
    </geometry>
    <material name="silver"/>
  </visual>
  <collision>
    <origin rpy="0 0 0" xyz="-0.255193 -0.000397 -0.047589"/>
    <geometry>
      <mesh filename="package://braco_v2_description/meshes/corpo_garra_1.stl" scale="0.001 0.001 0.001"/>
    </geometry>
  </collision>
</link>

<link name="Bearing_guide_v1_1">
  <inertial>
    <origin rpy="0 0 0" xyz="-3.6128666541790366e-07 3.972064564522655e-09 0.017250496155362758"/>
    <mass value="0.0016815613439380714"/>
    <inertia ixx="0.0" ixy="0.0" ixz="0.0" iyy="0.0" iyz="-0.0" izz="0.0"/>
  </inertial>
  <visual>
    <origin rpy="0 0 0" xyz="-0.329943 -0.000397 -0.030339"/>
    <geometry>
      <mesh filename="package://braco_v2_description/meshes/Bearing_guide_v1_1.stl" scale="0.001 0.001 0.001"/>
    </geometry>
    <material name="silver"/>
  </visual>
  <collision>
    <origin rpy="0 0 0" xyz="-0.329943 -0.000397 -0.030339"/>
    <geometry>
      <mesh filename="package://braco_v2_description/meshes/Bearing_guide_v1_1.stl" scale="0.001 0.001 0.001"/>
    </geometry>
  </collision>
</link>

<link name="Bearing_top-bottom_bushing_v1_1">
  <inertial>
    <origin rpy="0 0 0" xyz="-3.612866658064817e-07 3.972463773942517e-09 -0.001749503844637637"/>
    <mass value="0.0016106179771745465"/>
    <inertia ixx="0.0" ixy="-0.0" ixz="0.0" iyy="0.0" iyz="0.0" izz="0.0"/>
  </inertial>
  <visual>
    <origin rpy="0 0 0" xyz="-0.329943 -0.000397 -0.059839"/>
    <geometry>
      <mesh filename="package://braco_v2_description/meshes/Bearing_top-bottom_bushing_v1_1.stl" scale="0.001 0.001 0.001"/>
    </geometry>
    <material name="silver"/>
  </visual>
  <collision>
    <origin rpy="0 0 0" xyz="-0.329943 -0.000397 -0.059839"/>
    <geometry>
      <mesh filename="package://braco_v2_description/meshes/Bearing_top-bottom_bushing_v1_1.stl" scale="0.001 0.001 0.001"/>
    </geometry>
  </collision>
</link>

<link name="Bearing_top-bottom_bushing_v1__1__1">
  <inertial>
    <origin rpy="0 0 0" xyz="-3.6128666552892597e-07 3.972463658366565e-09 0.0017504961553626089"/>
    <mass value="0.0016106179771745465"/>
    <inertia ixx="0.0" ixy="0.0" ixz="0.0" iyy="0.0" iyz="0.0" izz="0.0"/>
  </inertial>
  <visual>
    <origin rpy="0 0 0" xyz="-0.329943 -0.000397 -0.035339"/>
    <geometry>
      <mesh filename="package://braco_v2_description/meshes/Bearing_top-bottom_bushing_v1__1__1.stl" scale="0.001 0.001 0.001"/>
    </geometry>
    <material name="silver"/>
  </visual>
  <collision>
    <origin rpy="0 0 0" xyz="-0.329943 -0.000397 -0.035339"/>
    <geometry>
      <mesh filename="package://braco_v2_description/meshes/Bearing_top-bottom_bushing_v1__1__1.stl" scale="0.001 0.001 0.001"/>
    </geometry>
  </collision>
</link>

<link name="Bearing_center_bushing_v1_1">
  <inertial>
    <origin rpy="0 0 0" xyz="0.053721638713334574 0.037714003972463724 0.11753649615536262"/>
    <mass value="0.0034513242368025996"/>
    <inertia ixx="0.0" ixy="0.0" ixz="-0.0" iyy="0.0" iyz="0.0" izz="0.0"/>
  </inertial>
  <visual>
    <origin rpy="0 0 0" xyz="-0.276221 0.037317 0.069947"/>
    <geometry>
      <mesh filename="package://braco_v2_description/meshes/Bearing_center_bushing_v1_1.stl" scale="0.001 0.001 0.001"/>
    </geometry>
    <material name="silver"/>
  </visual>
  <collision>
    <origin rpy="0 0 0" xyz="-0.276221 0.037317 0.069947"/>
    <geometry>
      <mesh filename="package://braco_v2_description/meshes/Bearing_center_bushing_v1_1.stl" scale="0.001 0.001 0.001"/>
    </geometry>
  </collision>
</link>

<link name="servo_garra_1">
  <inertial>
    <origin rpy="0 0 0" xyz="0.00877771088631396 -0.022783770578142928 0.08636982017301618"/>
    <mass value="0.25257832542625036"/>
    <inertia ixx="4.1e-05" ixy="-0.0" ixz="1e-06" iyy="6.8e-05" iyz="0.0" izz="4.4e-05"/>
  </inertial>
  <visual>
    <origin rpy="0 0 0" xyz="-0.286221 -0.023183 0.069947"/>
    <geometry>
      <mesh filename="package://braco_v2_description/meshes/servo_garra_1.stl" scale="0.001 0.001 0.001"/>
    </geometry>
    <material name="silver"/>
  </visual>
  <collision>
    <origin rpy="0 0 0" xyz="-0.286221 -0.023183 0.069947"/>
    <geometry>
      <mesh filename="package://braco_v2_description/meshes/servo_garra_1.stl" scale="0.001 0.001 0.001"/>
    </geometry>
  </collision>
</link>

<link name="Gripper_120T_v1_1">
  <inertial>
    <origin rpy="0 0 0" xyz="0.010502021200329559 0.01817352441983675 0.006028973064765866"/>
    <mass value="0.031315152970389164"/>
    <inertia ixx="1e-05" ixy="-4e-06" ixz="-3e-06" iyy="4e-05" iyz="-0.0" izz="4.8e-05"/>
  </inertial>
  <visual>
    <origin rpy="0 0 0" xyz="-0.329943 -0.000397 -0.038839"/>
    <geometry>
      <mesh filename="package://braco_v2_description/meshes/Gripper_120T_v1_1.stl" scale="0.001 0.001 0.001"/>
    </geometry>
    <material name="silver"/>
  </visual>
  <collision>
    <origin rpy="0 0 0" xyz="-0.329943 -0.000397 -0.038839"/>
    <geometry>
      <mesh filename="package://braco_v2_description/meshes/Gripper_120T_v1_1.stl" scale="0.001 0.001 0.001"/>
    </geometry>
  </collision>
</link>

<link name="Gripper_72T_v1_1">
  <inertial>
    <origin rpy="0 0 0" xyz="0.020483598648374624 -0.01768686032720034 -0.001221135191592282"/>
    <mass value="0.0250024753894087"/>
    <inertia ixx="4e-06" ixy="2e-06" ixz="2e-06" iyy="2e-05" iyz="-0.0" izz="2.2e-05"/>
  </inertial>
  <visual>
    <origin rpy="0 0 0" xyz="-0.329943 -0.000397 -0.051339"/>
    <geometry>
      <mesh filename="package://braco_v2_description/meshes/Gripper_72T_v1_1.stl" scale="0.001 0.001 0.001"/>
    </geometry>
    <material name="silver"/>
  </visual>
  <collision>
    <origin rpy="0 0 0" xyz="-0.329943 -0.000397 -0.051339"/>
    <geometry>
      <mesh filename="package://braco_v2_description/meshes/Gripper_72T_v1_1.stl" scale="0.001 0.001 0.001"/>
    </geometry>
  </collision>
</link>

<link name="Servo_gear_v1_1">
  <inertial>
    <origin rpy="0 0 0" xyz="-3.298847365829083e-07 2.5748186301626603e-07 0.004318374627694445"/>
    <mass value="0.010154744217590462"/>
    <inertia ixx="1e-06" ixy="0.0" ixz="0.0" iyy="1e-06" iyz="0.0" izz="1e-06"/>
  </inertial>
  <visual>
    <origin rpy="0 0 0" xyz="-0.285023 -0.000399 -0.041649"/>
    <geometry>
      <mesh filename="package://braco_v2_description/meshes/Servo_gear_v1_1.stl" scale="0.001 0.001 0.001"/>
    </geometry>
    <material name="silver"/>
  </visual>
  <collision>
    <origin rpy="0 0 0" xyz="-0.285023 -0.000399 -0.041649"/>
    <geometry>
      <mesh filename="package://braco_v2_description/meshes/Servo_gear_v1_1.stl" scale="0.001 0.001 0.001"/>
    </geometry>
  </collision>
</link>

<link name="tampa_1">
  <inertial>
    <origin rpy="0 0 0" xyz="-6.3483781470426774e-06 -1.751400612908694e-06 0.001500000000000029"/>
    <mass value="0.03288605303938267"/>
    <inertia ixx="2.7e-05" ixy="0.0" ixz="-0.0" iyy="2.7e-05" iyz="0.0" izz="5.4e-05"/>
  </inertial>
  <visual>
    <origin rpy="0 0 0" xyz="-0.0 -0.0 -0.04"/>
    <geometry>
      <mesh filename="package://braco_v2_description/meshes/tampa_1.stl" scale="0.001 0.001 0.001"/>
    </geometry>
    <material name="silver"/>
  </visual>
  <collision>
    <origin rpy="0 0 0" xyz="-0.0 -0.0 -0.04"/>
    <geometry>
      <mesh filename="package://braco_v2_description/meshes/tampa_1.stl" scale="0.001 0.001 0.001"/>
    </geometry>
  </collision>
</link>

<joint name="Rigid28" type="fixed">
  <origin rpy="0 0 0" xyz="-0.014425 -0.10175 0.040109"/>
  <parent link="Base_servo_mount_left_1"/>
  <child link="servo_left_1"/>
</joint>

<joint name="Rigid37" type="fixed">
  <origin rpy="0 0 0" xyz="-0.08132 0.10175 -0.039311"/>
  <parent link="Base_servo_mount_right_v1_1"/>
  <child link="servo_right_1"/>
</joint>

<joint name="Rev52" type="continuous">
  <origin rpy="0 0 0" xyz="0.124991 0.233175 -0.021626"/>
  <parent link="servo_elbow_1"/>
  <child link="Center_arm_v1_1"/>
  <axis xyz="0.0 1.0 -0.0"/>
</joint>

<joint name="Rigid54" type="fixed">
  <origin rpy="0 0 0" xyz="0.008486 0.02 -0.008485"/>
  <parent link="Center_arm_v1_1"/>
  <child link="Center_arm_bearing_guide_v1_1"/>
</joint>

<joint name="Rigid56" type="fixed">
  <origin rpy="0 0 0" xyz="0.008486 0.02 -0.109014"/>
  <parent link="Center_arm_v1_1"/>
  <child link="Center_arm_bearing_guide_v1__1__1"/>
</joint>

<joint name="Rigid58" type="fixed">
  <origin rpy="0 0 0" xyz="-0.008486 0.0134 0.008485"/>
  <parent link="Center_arm_bearing_guide_v1_1"/>
  <child link="Center_arm_bearing_guide_clamp_v1_1"/>
</joint>

<joint name="Rev63" type="continuous">
  <origin rpy="0 0 0" xyz="0.065443 -0.08794 0.082481"/>
  <parent link="servo_right_1"/>
  <child link="ombro_1"/>
  <axis xyz="0.0 1.0 0.0"/>
</joint>

<joint name="Rigid65" type="fixed">
  <origin rpy="0 0 0" xyz="0.042109 -0.221865 0.100861"/>
  <parent link="ombro_1"/>
  <child link="servo_elbow_1"/>
</joint>

<joint name="Rigid70" type="fixed">
  <origin rpy="0 0 0" xyz="-0.19951 0.18379 0.254315"/>
  <parent link="punho_1"/>
  <child link="servo_punho_rot_1"/>
</joint>

<joint name="Rev71" type="continuous">
  <origin rpy="0 0 0" xyz="0.0 0.0 -0.1175"/>
  <parent link="Center_arm_v1_1"/>
  <child link="servo_punho_xy_1"/>
  <axis xyz="-0.0 -1.0 0.0"/>
</joint>

<joint name="Rigid72" type="fixed">
  <origin rpy="0 0 0" xyz="0.165141 -0.061837 -0.028"/>
  <parent link="servo_punho_xy_1"/>
  <child link="punho_1"/>
</joint>

<joint name="Rigid74" type="fixed">
  <origin rpy="0 0 0" xyz="-0.008486 0.0134 -0.008486"/>
  <parent link="Center_arm_bearing_guide_v1__1__1"/>
  <child link="Center_arm_bearing_guide_clamp_v1_punho_1"/>
</joint>

<joint name="Rigid77" type="fixed">
  <origin rpy="0 0 0" xyz="0.017324 0.037609 0.003"/>
  <parent link="tampa_1"/>
  <child link="Base_servo_mount_left_1"/>
</joint>

<joint name="Rigid78" type="fixed">
  <origin rpy="0 0 0" xyz="0.01732 -0.036811 0.003"/>
  <parent link="tampa_1"/>
  <child link="Base_servo_mount_right_v1_1"/>
</joint>

<joint name="Rev81" type="continuous">
  <origin rpy="0 0 0" xyz="0.121019 -0.109865 -0.226631"/>
  <parent link="servo_punho_rot_1"/>
  <child link="corpo_garra_1"/>
  <axis xyz="1.0 0.0 0.0"/>
</joint>

<joint name="Rigid82" type="fixed">
  <origin rpy="0 0 0" xyz="0.07475 0.0 -0.01725"/>
  <parent link="corpo_garra_1"/>
  <child link="Bearing_guide_v1_1"/>
</joint>

<joint name="Rigid83" type="fixed">
  <origin rpy="0 0 0" xyz="0.07475 0.0 0.01225"/>
  <parent link="corpo_garra_1"/>
  <child link="Bearing_top-bottom_bushing_v1_1"/>
</joint>

<joint name="Rigid84" type="fixed">
  <origin rpy="0 0 0" xyz="0.07475 0.0 -0.01225"/>
  <parent link="corpo_garra_1"/>
  <child link="Bearing_top-bottom_bushing_v1__1__1"/>
</joint>

<joint name="Rigid85" type="fixed">
  <origin rpy="0 0 0" xyz="0.021028 -0.037714 -0.117536"/>
  <parent link="corpo_garra_1"/>
  <child link="Bearing_center_bushing_v1_1"/>
</joint>

<joint name="Rigid86" type="fixed">
  <origin rpy="0 0 0" xyz="0.031028 0.022786 -0.117536"/>
  <parent link="corpo_garra_1"/>
  <child link="servo_garra_1"/>
</joint>

<joint name="Rev87" type="revolute">
  <origin rpy="0 0 0" xyz="0.0 0.0 0.0035"/>
  <parent link="Bearing_top-bottom_bushing_v1__1__1"/>
  <child link="Gripper_120T_v1_1"/>
  <axis xyz="0.0 0.0 1.0"/>
  <limit effort="100" lower="0.0" upper="0.785398" velocity="100"/>
</joint>

<joint name="Rev88" type="revolute">
  <origin rpy="0 0 0" xyz="0.053722 0.037714 0.121286"/>
  <parent link="Bearing_center_bushing_v1_1"/>
  <child link="Gripper_72T_v1_1"/>
  <axis xyz="0.0 0.0 1.0"/>
  <limit effort="100" lower="-0.785398" upper="0.0" velocity="100"/>
</joint>

<joint name="Rev89" type="continuous">
  <origin rpy="0 0 0" xyz="-0.001198 -0.022784 0.111596"/>
  <parent link="servo_garra_1"/>
  <child link="Servo_gear_v1_1"/>
  <axis xyz="0.0 0.0 1.0"/>
</joint>

<joint name="Rev93" type="continuous">
  <origin rpy="0 0 0" xyz="0.0 0.0 0.04"/>
  <parent link="base_link"/>
  <child link="tampa_1"/>
  <axis xyz="0.0 0.0 1.0"/>
</joint>

</robot>
